Workbook

Sheet mem_dec
A1: 55 | B1: 246 | C1: 73 | D1: 86 | E1: i=0; i=4;
A2: 110 | B2: 211 | C2: 170 | D2: 152
A3: 198 | B3: 59 | C3: 216 | D3: 137 | P3: pos_out
A4: 1 | B4: 48 | C4: 165 | D4: 160 | O4: ch_out | P4: 0 | Q4: 1 | R4: 2 | S4: 3
A5: 23 | B5: 102 | C5: 120 | D5: 86 | O5: 0 | P5: =SUM(out_col0!A1:D20) -> 1087855 | Q5: =SUM(out_col1!A1:D20) -> 1146690
A6: 3 | B6: 95 | C6: 246 | D6: 145 | O6: 1 | P6: =SUM(out_col0!A21:D40) -> 1313896
A7: 120 | B7: 54 | C7: 123 | D7: 233 | O7: 2 | P7: =SUM(out_col0!A41:D60) -> 1292576
A8: 254 | B8: 26 | C8: 134 | D8: 157 | O8: 3
A9: 234 | B9: 99 | C9: 181 | D9: 48 | O9: 4
A10: 65 | B10: 15 | C10: 74 | D10: 57 | O10: 5
A11: 31 | B11: 79 | C11: 18 | D11: 71 | O11: 6
A12: 118 | B12: 201 | C12: 21 | D12: 88 | O12: 7
A13: 173 | B13: 66 | C13: 35 | D13: 182 | O13: 8
A14: 183 | B14: 24 | C14: 115 | D14: 214
A15: 45 | B15: 103 | C15: 131 | D15: 247
A16: 3 | B16: 221 | C16: 47 | D16: 228
A17: 21 | B17: 86 | C17: 139 | D17: 183
A18: 98 | B18: 206 | C18: 97 | D18: 27
A19: 248 | B19: 117 | C19: 171 | D19: 144
A20: 159 | B20: 76 | C20: 96 | D20: 9
A21: 34 | B21: 190 | C21: 219 | D21: 56 | E21: i=1; i=5;
A22: 157 | B22: 1 | C22: 216 | D22: 85
A23: 153 | B23: 148 | C23: 82 | D23: 155
A24: 73 | B24: 45 | C24: 10 | D24: 220
A25: 221 | B25: 93 | C25: 149 | D25: 234
A26: 122 | B26: 57 | C26: 91 | D26: 57
A27: 247 | B27: 2 | C27: 139 | D27: 233 | G27: =mem_dec!A1*mem_dec!A82 -> 8525
A28: 29 | B28: 202 | C28: 66 | D28: 104
A29: 182 | B29: 165 | C29: 187 | D29: 148
A30: 177 | B30: 249 | C30: 146 | D30: 234
A31: 94 | B31: 217 | C31: 59 | D31: 211
A32: 146 | B32: 113 | C32: 61 | D32: 144
A33: 203 | B33: 232 | C33: 100 | D33: 167
A34: 175 | B34: 226 | C34: 215 | D34: 226
A35: 30 | B35: 207 | C35: 147 | D35: 220
A36: 47 | B36: 59 | C36: 86 | D36: 37
A37: 10 | B37: 137 | C37: 85 | D37: 135
A38: 17 | B38: 235 | C38: 116 | D38: 77
A39: 35 | B39: 236 | C39: 77 | D39: 57
A40: 48 | B40: 77 | C40: 105 | D40: 61
...

Sheet mem_hex
A1: =DEC2HEX(mem_dec!A1) -> 37 | B1: =DEC2HEX(mem_dec!B1) -> F6 | C1: =DEC2HEX(mem_dec!C1) -> 49 | D1: =DEC2HEX(mem_dec!D1) -> 56 | E1: i=0; i=4; | F1: 2D6783F7
A2: =DEC2HEX(mem_dec!A2) -> 6E | B2: =DEC2HEX(mem_dec!B2) -> D3 | C2: =DEC2HEX(mem_dec!C2) -> AA | D2: =DEC2HEX(mem_dec!D2) -> 98 | F2: 03DD2FE4
A3: =DEC2HEX(mem_dec!A3) -> C6 | B3: =DEC2HEX(mem_dec!B3) -> 3B | C3: =DEC2HEX(mem_dec!C3) -> D8 | D3: =DEC2HEX(mem_dec!D3) -> 89
A4: =DEC2HEX(mem_dec!A4) -> 1 | B4: =DEC2HEX(mem_dec!B4) -> 30 | C4: =DEC2HEX(mem_dec!C4) -> A5 | D4: =DEC2HEX(mem_dec!D4) -> A0
A5: =DEC2HEX(mem_dec!A5) -> 17 | B5: =DEC2HEX(mem_dec!B5) -> 66 | C5: =DEC2HEX(mem_dec!C5) -> 78 | D5: =DEC2HEX(mem_dec!D5) -> 56
A6: =DEC2HEX(mem_dec!A6) -> 3 | B6: =DEC2HEX(mem_dec!B6) -> 5F | C6: =DEC2HEX(mem_dec!C6) -> F6 | D6: =DEC2HEX(mem_dec!D6) -> 91
A7: =DEC2HEX(mem_dec!A7) -> 78 | B7: =DEC2HEX(mem_dec!B7) -> 36 | C7: =DEC2HEX(mem_dec!C7) -> 7B | D7: =DEC2HEX(mem_dec!D7) -> E9
A8: =DEC2HEX(mem_dec!A8) -> FE | B8: =DEC2HEX(mem_dec!B8) -> 1A | C8: =DEC2HEX(mem_dec!C8) -> 86 | D8: =DEC2HEX(mem_dec!D8) -> 9D
A9: =DEC2HEX(mem_dec!A9) -> EA | B9: =DEC2HEX(mem_dec!B9) -> 63 | C9: =DEC2HEX(mem_dec!C9) -> B5 | D9: =DEC2HEX(mem_dec!D9) -> 30
A10: =DEC2HEX(mem_dec!A10) -> 41 | B10: =DEC2HEX(mem_dec!B10) -> F | C10: =DEC2HEX(mem_dec!C10) -> 4A | D10: =DEC2HEX(mem_dec!D10) -> 39
A11: =DEC2HEX(mem_dec!A11) -> 1F | B11: =DEC2HEX(mem_dec!B11) -> 4F | C11: =DEC2HEX(mem_dec!C11) -> 12 | D11: =DEC2HEX(mem_dec!D11) -> 47
A12: =DEC2HEX(mem_dec!A12) -> 76 | B12: =DEC2HEX(mem_dec!B12) -> C9 | C12: =DEC2HEX(mem_dec!C12) -> 15 | D12: =DEC2HEX(mem_dec!D12) -> 58
A13: =DEC2HEX(mem_dec!A13) -> AD | B13: =DEC2HEX(mem_dec!B13) -> 42 | C13: =DEC2HEX(mem_dec!C13) -> 23 | D13: =DEC2HEX(mem_dec!D13) -> B6
A14: =DEC2HEX(mem_dec!A14) -> B7 | B14: =DEC2HEX(mem_dec!B14) -> 18 | C14: =DEC2HEX(mem_dec!C14) -> 73 | D14: =DEC2HEX(mem_dec!D14) -> D6
... A20: =DEC2HEX(mem_dec!A20) -> 9F | B20: =DEC2HEX(mem_dec!B20) -> 4C | C20: =DEC2HEX(mem_dec!C20) -> 60 | D20: =DEC2HEX(mem_dec!D20) -> 9
A21: =DEC2HEX(mem_dec!A21) -> 22 | B21: =DEC2HEX(mem_dec!B21) -> BE | C21: =DEC2HEX(mem_dec!C21) -> DB | D21: =DEC2HEX(mem_dec!D21) -> 38 | E21: i=1; i=5;
A22: =DEC2HEX(mem_dec!A22) -> 9D | B22: =DEC2HEX(mem_dec!B22) -> 1 | C22: =DEC2HEX(mem_dec!C22) -> D8 | D22: =DEC2HEX(mem_dec!D22) -> 55
A23: =DEC2HEX(mem_dec!A23) -> 99 | B23: =DEC2HEX(mem_dec!B23) -> 94 | C23: =DEC2HEX(mem_dec!C23) -> 52 | D23: =DEC2HEX(mem_dec!D23) -> 9B
A24: =DEC2HEX(mem_dec!A24) -> 49 | B24: =DEC2HEX(mem_dec!B24) -> 2D | C24: =DEC2HEX(mem_dec!C24) -> A | D24: =DEC2HEX(mem_dec!D24) -> DC
A25: =DEC2HEX(mem_dec!A25) -> DD | B25: =DEC2HEX(mem_dec!B25) -> 5D | C25: =DEC2HEX(mem_dec!C25) -> 95 | D25: =DEC2HEX(mem_dec!D25) -> EA
A26: =DEC2HEX(mem_dec!A26) -> 7A | B26: =DEC2HEX(mem_dec!B26) -> 39 | C26: =DEC2HEX(mem_dec!C26) -> 5B | D26: =DEC2HEX(mem_dec!D26) -> 39
A27: =DEC2HEX(mem_dec!A27) -> F7 | B27: =DEC2HEX(mem_dec!B27) -> 2 | C27: =DEC2HEX(mem_dec!C27) -> 8B | D27: =DEC2HEX(mem_dec!D27) -> E9
A28: =DEC2HEX(mem_dec!A28) -> 1D | B28: =DEC2HEX(mem_dec!B28) -> CA | C28: =DEC2HEX(mem_dec!C28) -> 42 | D28: =DEC2HEX(mem_dec!D28) -> 68
A29: =DEC2HEX(mem_dec!A29) -> B6 | B29: =DEC2HEX(mem_dec!B29) -> A5 | C29: =DEC2HEX(mem_dec!C29) -> BB | D29: =DEC2HEX(mem_dec!D29) -> 94
A30: =DEC2HEX(mem_dec!A30) -> B1 | B30: =DEC2HEX(mem_dec!B30) -> F9 | C30: =DEC2HEX(mem_dec!C30) -> 92 | D30: =DEC2HEX(mem_dec!D30) -> EA
A31: =DEC2HEX(mem_dec!A31) -> 5E | B31: =DEC2HEX(mem_dec!B31) -> D9 | C31: =DEC2HEX(mem_dec!C31) -> 3B | D31: =DEC2HEX(mem_dec!D31) -> D3
A32: =DEC2HEX(mem_dec!A32) -> 92 | B32: =DEC2HEX(mem_dec!B32) -> 71 | C32: =DEC2HEX(mem_dec!C32) -> 3D | D32: =DEC2HEX(mem_dec!D32) -> 90
A33: =DEC2HEX(mem_dec!A33) -> CB | B33: =DEC2HEX(mem_dec!B33) -> E8 | C33: =DEC2HEX(mem_dec!C33) -> 64 | D33: =DEC2HEX(mem_dec!D33) -> A7
... A40: =DEC2HEX(mem_dec!A40) -> 30 | B40: =DEC2HEX(mem_dec!B40) -> 4D | C40: =DEC2HEX(mem_dec!C40) -> 69 | D40: =DEC2HEX(mem_dec!D40) -> 3D
A41: =DEC2HEX(mem_dec!A41) -> 3C | B41: =DEC2HEX(mem_dec!B41) -> A | C41: =DEC2HEX(mem_dec!C41) -> EB | D41: =DEC2HEX(mem_dec!D41) -> 6B | E41: i=2; i=6;
A42: =DEC2HEX(mem_dec!A42) -> 1E | B42: =DEC2HEX(mem_dec!B42) -> 31 | C42: =DEC2HEX(mem_dec!C42) -> A9 | D42: =DEC2HEX(mem_dec!D42) -> C2
A43: =DEC2HEX(mem_dec!A43) -> 5F | B43: =DEC2HEX(mem_dec!B43) -> A3 | C43: =DEC2HEX(mem_dec!C43) -> 47 | D43: =DEC2HEX(mem_dec!D43) -> E1
A44: =DEC2HEX(mem_dec!A44) -> FD | B44: =DEC2HEX(mem_dec!B44) -> F1 | C44: =DEC2HEX(mem_dec!C44) -> 94 | D44: =DEC2HEX(mem_dec!D44) -> 3A
A45: =DEC2HEX(mem_dec!A45) -> F2 | B45: =DEC2HEX(mem_dec!B45) -> F1 | C45: =DEC2HEX(mem_dec!C45) -> 91 | D45: =DEC2HEX(mem_dec!D45) -> FC
A46: =DEC2HEX(mem_dec!A46) -> 14 | B46: =DEC2HEX(mem_dec!B46) -> D8 | C46: =DEC2HEX(mem_dec!C46) -> 5 | D46: =DEC2HEX(mem_dec!D46) -> 74
A47: =DEC2HEX(mem_dec!A47) -> ED | B47: =DEC2HEX(mem_dec!B47) -> 93 | C47: =DEC2HEX(mem_dec!C47) -> 22 | D47: =DEC2HEX(mem_dec!D47) -> 86
A48: =DEC2HEX(mem_dec!A48) -> 86 | B48: =DEC2HEX(mem_dec!B48) -> 19 | C48: =DEC2HEX(mem_dec!C48) -> DC | D48: =DEC2HEX(mem_dec!D48) -> B
A49: =DEC2HEX(mem_dec!A49) -> 9E | B49: =DEC2HEX(mem_dec!B49) -> 36 | C49: =DEC2HEX(mem_dec!C49) -> 8D | D49: =DEC2HEX(mem_dec!D49) -> 9B
A50: =DEC2HEX(mem_dec!A50) -> 71 | B50: =DEC2HEX(mem_dec!B50) -> 91 | C50: =DEC2HEX(mem_dec!C50) -> 2D | D50: =DEC2HEX(mem_dec!D50) -> D8
A51: =DEC2HEX(mem_dec!A51) -> 5F | B51: =DEC2HEX(mem_dec!B51) -> 26 | C51: =DEC2HEX(mem_dec!C51) -> BF | D51: =DEC2HEX(mem_dec!D51) -> CE
...

Sheet out_col0
A1: =mem_dec!A1*mem_dec!A81 -> 0 | B1: =mem_dec!B1*mem_dec!B81 -> 9348 | C1: =mem_dec!C1*mem_dec!C81 -> 2263 | D1: =mem_dec!D1*mem_dec!D81 -> 7138 | F1: =SUM(A1:D1) -> 18749 | H1: 1 | I1: =F1+F6+F11+F16 -> 138207
A2: =mem_dec!A2*mem_dec!A82 -> 17050 | B2: =mem_dec!B2*mem_dec!B82 -> 211 | C2: =mem_dec!C2*mem_dec!C82 -> 26180 | D2: =mem_dec!D2*mem_dec!D82 -> 7144 | F2: =SUM(A2:D2) -> 50585 | H2: 2 | I2: =F2+F7+F12+F17 -> 254087
A3: =mem_dec!A3*mem_dec!A83 -> 25542 | B3: =mem_dec!B3*mem_dec!B83 -> 12685 | C3: =mem_dec!C3*mem_dec!C83 -> 1080 | D3: =mem_dec!D3*mem_dec!D83 -> 11508 | F3: =SUM(A3:D3) -> 50815 | H3: 3 | I3: =F3+F8+F13+F18 -> 236737
A4: =mem_dec!A4*mem_dec!A84 -> 183 | B4: =mem_dec!B4*mem_dec!B84 -> 240 | C4: =mem_dec!C4*mem_dec!C84 -> 11880 | D4: =mem_dec!D4*mem_dec!D84 -> 4320 | F4: =SUM(A4:D4) -> 16623 | H4: 4 | I4: =F4+F9+F14+F19 -> 255022
A5: =mem_dec!A5*mem_dec!A85 -> 5727 | B5: =mem_dec!B5*mem_dec!B85 -> 16422 | C5: =mem_dec!C5*mem_dec!C85 -> 3600 | D5: =mem_dec!D5*mem_dec!D85 -> 18576 | F5: =SUM(A5:D5) -> 44325 | H5: 5 | I5: =F5+F10+F15+F20 -> 203802
A6: =mem_dec!A6*mem_dec!A89 -> 504 | B6: =mem_dec!B6*mem_dec!B89 -> 9120 | C6: =mem_dec!C6*mem_dec!C89 -> 19188 | D6: =mem_dec!D6*mem_dec!D89 -> 5655 | F6: =SUM(A6:D6) -> 34467 | H6: somma | I6: =SUM(I1:I5) -> 1087855
A7: =mem_dec!A7*mem_dec!A90 -> 25560 | B7: =mem_dec!B7*mem_dec!B90 -> 5886 | C7: =mem_dec!C7*mem_dec!C90 -> 18327 | D7: =mem_dec!D7*mem_dec!D90 -> 53823 | F7: =SUM(A7:D7) -> 103596
A8: =mem_dec!A8*mem_dec!A91 -> 54102 | B8: =mem_dec!B8*mem_dec!B91 -> 1092 | C8: =mem_dec!C8*mem_dec!C91 -> 13400 | D8: =mem_dec!D8*mem_dec!D91 -> 32813 | F8: =SUM(A8:D8) -> 101407
A9: =mem_dec!A9*mem_dec!A92 -> 45162 | B9: =mem_dec!B9*mem_dec!B92 -> 2871 | C9: =mem_dec!C9*mem_dec!C92 -> 43802 | D9: =mem_dec!D9*mem_dec!D92 -> 2592 | F9: =SUM(A9:D9) -> 94427
A10: =mem_dec!A10*mem_dec!A93 -> 13910 | B10: =mem_dec!B10*mem_dec!B93 -> 3825 | C10: =mem_dec!C10*mem_dec!C93 -> 3182 | D10: =mem_dec!D10*mem_dec!D93 -> 13110 | F10: =SUM(A10:D10) -> 34027
A11: =mem_dec!A11*mem_dec!A97 -> 2666 | B11: =mem_dec!B11*mem_dec!B97 -> 5688 | C11: =mem_dec!C11*mem_dec!C97 -> 486 | D11: =mem_dec!D11*mem_dec!D97 -> 10579 | F11: =SUM(A11:D11) -> 19419
A12: =mem_dec!A12*mem_dec!A98 -> 16992 | B12: =mem_dec!B12*mem_dec!B98 -> 7437 | C12: =mem_dec!C12*mem_dec!C98 -> 1218 | D12: =mem_dec!D12*mem_dec!D98 -> 19096 | F12: =SUM(A12:D12) -> 44743
A13: =mem_dec!A13*mem_dec!A99 -> 12110 | B13: =mem_dec!B13*mem_dec!B99 -> 3036 | C13: =mem_dec!C13*mem_dec!C99 -> 910 | D13: =mem_dec!D13*mem_dec!D99 -> 4914 | F13: =SUM(A13:D13) -> 20970
A14: =mem_dec!A14*mem_dec!A100 -> 27084 | B14: =mem_dec!B14*mem_dec!B100 -> 3648 | C14: =mem_dec!C14*mem_dec!C100 -> 17020 | D14: =mem_dec!D14*mem_dec!D100 -> 7918 | F14: =SUM(A14:D14) -> 55670
A15: =mem_dec!A15*mem_dec!A101 -> 11115 | B15: =mem_dec!B15*mem_dec!B101 -> 16892 | C15: =mem_dec!C15*mem_dec!C101 -> 5109 | D15: =mem_dec!D15*mem_dec!D101 -> 52611 | F15: =SUM(A15:D15) -> 85727
A16: =mem_dec!A16*mem_dec!A105 -> 573 | B16: =mem_dec!B16*mem_dec!B105 -> 51714 | C16: =mem_dec!C16*mem_dec!C105 -> 517 | D16: =mem_dec!D16*mem_dec!D105 -> 12768 | F16: =SUM(A16:D16) -> 65572
A17: =mem_dec!A17*mem_dec!A106 -> 2709 | B17: =mem_dec!B17*mem_dec!B106 -> 7654 | C17: =mem_dec!C17*mem_dec!C106 -> 22657 | D17: =mem_dec!D17*mem_dec!D106 -> 22143 | F17: =SUM(A17:D17) -> 55163
A18: =mem_dec!A18*mem_dec!A107 -> 8624 | B18: =mem_dec!B18*mem_dec!B107 -> 41200 | C18: =mem_dec!C18*mem_dec!C107 -> 10670 | D18: =mem_dec!D18*mem_dec!D107 -> 3051 | F18: =SUM(A18:D18) -> 63545
A19: =mem_dec!A19*mem_dec!A108 -> 32736 | B19: =mem_dec!B19*mem_dec!B108 -> 1638 | C19: =mem_dec!C19*mem_dec!C108 -> 34200 | D19: =mem_dec!D19*mem_dec!D108 -> 19728 | F19: =SUM(A19:D19) -> 88302
A20: =mem_dec!A20*mem_dec!A109 -> 2067 | B20: =mem_dec!B20*mem_dec!B109 -> 11856 | C20: =mem_dec!C20*mem_dec!C109 -> 24288 | D20: =mem_dec!D20*mem_dec!D109 -> 1512 | F20: =SUM(A20:D20) -> 39723
A21: =mem_dec!A21*mem_dec!A81 -> 0 | B21: =mem_dec!B21*mem_dec!B81 -> 7220 | C21: =mem_dec!C21*mem_dec!C81 -> 6789 | D21: =mem_dec!D21*mem_dec!D81 -> 4648 | F21: =SUM(A21:D21) -> 18657 | H21: 1 | I21: =F21+F26+F31+F36 -> 136487
A22: =mem_dec!A22*mem_dec!A82 -> 24335 | B22: =mem_dec!B22*mem_dec!B82 -> 1 | C22: =mem_dec!C22*mem_dec!C82 -> 33264 | D22: =mem_dec!D22*mem_dec!D82 -> 3995 | F22: =SUM(A22:D22) -> 61595 | H22: 2 | I22: =F22+F27+F32+F37 -> 292622 | J22: =I21+I22 -> 429109
A23: =mem_dec!A23*mem_dec!A83 -> 19737 | B23: =mem_dec!B23*mem_dec!B83 -> 31820 | C23: =mem_dec!C23*mem_dec!C83 -> 410 | D23: =mem_dec!D23*mem_dec!D83 -> 13020 | F23: =SUM(A23:D23) -> 64987 | H23: 3 | I23: =F23+F28+F33+F38 -> 209932 | J23: =J22+I23 -> 639041
A24: =mem_dec!A24*mem_dec!A84 -> 13359 | B24: =mem_dec!B24*mem_dec!B84 -> 225 | C24: =mem_dec!C24*mem_dec!C84 -> 720 | D24: =mem_dec!D24*mem_dec!D84 -> 5940 | F24: =SUM(A24:D24) -> 20244 | H24: 4 | I24: =F24+F29+F34+F39 -> 244968 | J24: =J23+I24 -> 884009
A25: =mem_dec!A25*mem_dec!A85 -> 55029 | B25: =mem_dec!B25*mem_dec!B85 -> 14973 | C25: =mem_dec!C25*mem_dec!C85 -> 4470 | D25: =mem_dec!D25*mem_dec!D85 -> 50544 | F25: =SUM(A25:D25) -> 125016 | H25: 5 | I25: =F25+F30+F35+F40 -> 429887 | J25: =J24+I25 -> 1313896
A26: =mem_dec!A26*mem_dec!A89 -> 20496 | B26: =mem_dec!B26*mem_dec!B89 -> 5472 | C26: =mem_dec!C26*mem_dec!C89 -> 7098 | D26: =mem_dec!D26*mem_dec!D89 -> 2223 | F26: =SUM(A26:D26) -> 35289 | H26: somma | I26: =SUM(I21:I25) -> 1313896
A27: =mem_dec!A27*mem_dec!A90 -> 52611 | B27: =mem_dec!B27*mem_dec!B90 -> 218 | C27: =mem_dec!C27*mem_dec!C90 -> 20711 | D27: =mem_dec!D27*mem_dec!D90 -> 53823 | F27: =SUM(A27:D27) -> 127363
A28: =mem_dec!A28*mem_dec!A91 -> 6177 | B28: =mem_dec!B28*mem_dec!B91 -> 8484 | C28: =mem_dec!C28*mem_dec!C91 -> 6600 | D28: =mem_dec!D28*mem_dec!D91 -> 21736 | F28: =SUM(A28:D28) -> 42997
A29: =mem_dec!A29*mem_dec!A92 -> 35126 | B29: =mem_dec!B29*mem_dec!B92 -> 4785 | C29: =mem_dec!C29*mem_dec!C92 -> 45254 | D29: =mem_dec!D29*mem_dec!D92 -> 7992 | F29: =SUM(A29:D29) -> 93157
A30: =mem_dec!A30*mem_dec!A93 -> 37878 | B30: =mem_dec!B30*mem_dec!B93 -> 63495 | C30: =mem_dec!C30*mem_dec!C93 -> 6278 | D30: =mem_dec!D30*mem_dec!D93 -> 53820 | F30: =SUM(A30:D30) -> 161471
A31: =mem_dec!A31*mem_dec!A97 -> 8084 | B31: =mem_dec!B31*mem_dec!B97 -> 15624 | C31: =mem_dec!C31*mem_dec!C97 -> 1593 | D31: =mem_dec!D31*mem_dec!D97 -> 31439 | F31: =SUM(A31:D31) -> 56740
A32: =mem_dec!A32*mem_dec!A98 -> 21024 | B32: =mem_dec!B32*mem_dec!B98 -> 4181 | C32: =mem_dec!C32*mem_dec!C98 -> 3538 | D32: =mem_dec!D32*mem_dec!D98 -> 31248 | F32: =SUM(A32:D32) -> 59991
A33: =mem_dec!A33*mem_dec!A99 -> 14210 | B33: =mem_dec!B33*mem_dec!B99 -> 10672 | C33: =mem_dec!C33*mem_dec!C99 -> 2600 | D33: =mem_dec!D33*mem_dec!D99 -> 4509 | F33: =SUM(A33:D33) -> 31991
A34: =mem_dec!A34*mem_dec!A100 -> 25900 | B34: =mem_dec!B34*mem_dec!B100 -> 34352 | C34: =mem_dec!C34*mem_dec!C100 -> 31820 | D34: =mem_dec!D34*mem_dec!D100 -> 8362 | F34: =SUM(A34:D34) -> 100434
A35: =mem_dec!A35*mem_dec!A101 -> 7410 | B35: =mem_dec!B35*mem_dec!B101 -> 33948 | C35: =mem_dec!C35*mem_dec!C101 -> 5733 | D35: =mem_dec!D35*mem_dec!D101 -> 46860 | F35: =SUM(A35:D35) -> 93951
A36: =mem_dec!A36*mem_dec!A105 -> 8977 | B36: =mem_dec!B36*mem_dec!B105 -> 13806 | C36: =mem_dec!C36*mem_dec!C105 -> 946 | D36: =mem_dec!D36*mem_dec!D105 -> 2072 | F36: =SUM(A36:D36) -> 25801
A37: =mem_dec!A37*mem_dec!A106 -> 1290 | B37: =mem_dec!B37*mem_dec!B106 -> 12193 | C37: =mem_dec!C37*mem_dec!C106 -> 13855 | D37: =mem_dec!D37*mem_dec!D106 -> 16335 | F37: =SUM(A37:D37) -> 43673
A38: =mem_dec!A38*mem_dec!A107 -> 1496 | B38: =mem_dec!B38*mem_dec!B107 -> 47000 | C38: =mem_dec!C38*mem_dec!C107 -> 12760 | D38: =mem_dec!D38*mem_dec!D107 -> 8701 | F38: =SUM(A38:D38) -> 69957
A39: =mem_dec!A39*mem_dec!A108 -> 4620 | B39: =mem_dec!B39*mem_dec!B108 -> 3304 | C39: =mem_dec!C39*mem_dec!C108 -> 15400 | D39: =mem_dec!D39*mem_dec!D108 -> 7809 | F39: =SUM(A39:D39) -> 31133
A40: =mem_dec!A40*mem_dec!A109 -> 624 | B40: =mem_dec!B40*mem_dec!B109 -> 12012 | C40: =mem_dec!C40*mem_dec!C109 -> 26565 | D40: =mem_dec!D40*mem_dec!D109 -> 10248 | F40: =SUM(A40:D40) -> 49449
...

Sheet hex_out_col0
A1: =DEC2HEX(out_col0!A1) -> 0 | B1: =DEC2HEX(out_col0!B1) -> 2484 | C1: =DEC2HEX(out_col0!C1) -> 8D7 | D1: =DEC2HEX(out_col0!D1) -> 1BE2 | F1: =DEC2HEX(out_col0!F1) -> 493D | H1: =DEC2HEX(out_col0!H1) -> 1 | I1: =DEC2HEX(out_col0!I1) -> 21BDF
A2: =DEC2HEX(out_col0!A2) -> 429A | B2: =DEC2HEX(out_col0!B2) -> D3 | C2: =DEC2HEX(out_col0!C2) -> 6644 | D2: =DEC2HEX(out_col0!D2) -> 1BE8 | F2: =DEC2HEX(out_col0!F2) -> C599 | H2: =DEC2HEX(out_col0!H2) -> 2 | I2: =DEC2HEX(out_col0!I2) -> 3E087
A3: =DEC2HEX(out_col0!A3) -> 63C6 | B3: =DEC2HEX(out_col0!B3) -> 318D | C3: =DEC2HEX(out_col0!C3) -> 438 | D3: =DEC2HEX(out_col0!D3) -> 2CF4 | F3: =DEC2HEX(out_col0!F3) -> C67F | H3: =DEC2HEX(out_col0!H3) -> 3 | I3: =DEC2HEX(out_col0!I3) -> 39CC1
A4: =DEC2HEX(out_col0!A4) -> B7 | B4: =DEC2HEX(out_col0!B4) -> F0 | C4: =DEC2HEX(out_col0!C4) -> 2E68 | D4: =DEC2HEX(out_col0!D4) -> 10E0 | F4: =DEC2HEX(out_col0!F4) -> 40EF | H4: =DEC2HEX(out_col0!H4) -> 4 | I4: =DEC2HEX(out_col0!I4) -> 3E42E
A5: =DEC2HEX(out_col0!A5) -> 165F | B5: =DEC2HEX(out_col0!B5) -> 4026 | C5: =DEC2HEX(out_col0!C5) -> E10 | D5: =DEC2HEX(out_col0!D5) -> 4890 | F5: =DEC2HEX(out_col0!F5) -> AD25 | H5: =DEC2HEX(out_col0!H5) -> 5 | I5: =DEC2HEX(out_col0!I5) -> 31C1A
A6: =DEC2HEX(out_col0!A6) -> 1F8 | B6: =DEC2HEX(out_col0!B6) -> 23A0 | C6: =DEC2HEX(out_col0!C6) -> 4AF4 | D6: =DEC2HEX(out_col0!D6) -> 1617 | F6: =DEC2HEX(out_col0!F6) -> 86A3 | H6: somma | I6: =DEC2HEX(out_col0!I6) -> 10996F
A7: =DEC2HEX(out_col0!A7) -> 63D8 | B7: =DEC2HEX(out_col0!B7) -> 16FE | C7: =DEC2HEX(out_col0!C7) -> 4797 | D7: =DEC2HEX(out_col0!D7) -> D23F | F7: =DEC2HEX(out_col0!F7) -> 194AC
A8: =DEC2HEX(out_col0!A8) -> D356 | B8: =DEC2HEX(out_col0!B8) -> 444 | C8: =DEC2HEX(out_col0!C8) -> 3458 | D8: =DEC2HEX(out_col0!D8) -> 802D | F8: =DEC2HEX(out_col0!F8) -> 18C1F
A9: =DEC2HEX(out_col0!A9) -> B06A | B9: =DEC2HEX(out_col0!B9) -> B37 | C9: =DEC2HEX(out_col0!C9) -> AB1A | D9: =DEC2HEX(out_col0!D9) -> A20 | F9: =DEC2HEX(out_col0!F9) -> 170DB
A10: =DEC2HEX(out_col0!A10) -> 3656 | B10: =DEC2HEX(out_col0!B10) -> EF1 | C10: =DEC2HEX(out_col0!C10) -> C6E | D10: =DEC2HEX(out_col0!D10) -> 3336 | F10: =DEC2HEX(out_col0!F10) -> 84EB
A11: =DEC2HEX(out_col0!A11) -> A6A | B11: =DEC2HEX(out_col0!B11) -> 1638 | C11: =DEC2HEX(out_col0!C11) -> 1E6 | D11: =DEC2HEX(out_col0!D11) -> 2953 | F11: =DEC2HEX(out_col0!F11) -> 4BDB
A12: =DEC2HEX(out_col0!A12) -> 4260 | B12: =DEC2HEX(out_col0!B12) -> 1D0D | C12: =DEC2HEX(out_col0!C12) -> 4C2 | D12: =DEC2HEX(out_col0!D12) -> 4A98 | F12: =DEC2HEX(out_col0!F12) -> AEC7
A13: =DEC2HEX(out_col0!A13) -> 2F4E | B13: =DEC2HEX(out_col0!B13) -> BDC | C13: =DEC2HEX(out_col0!C13) -> 38E | D13: =DEC2HEX(out_col0!D13) -> 1332 | F13: =DEC2HEX(out_col0!F13) -> 51EA
A14: =DEC2HEX(out_col0!A14) -> 69CC | B14: =DEC2HEX(out_col0!B14) -> E40 | C14: =DEC2HEX(out_col0!C14) -> 427C | D14: =DEC2HEX(out_col0!D14) -> 1EEE | F14: =DEC2HEX(out_col0!F14) -> D976
A15: =DEC2HEX(out_col0!A15) -> 2B6B | B15: =DEC2HEX(out_col0!B15) -> 41FC | C15: =DEC2HEX(out_col0!C15) -> 13F5 | D15: =DEC2HEX(out_col0!D15) -> CD83 | F15: =DEC2HEX(out_col0!F15) -> 14EDF
A16: =DEC2HEX(out_col0!A16) -> 23D | B16: =DEC2HEX(out_col0!B16) -> CA02 | C16: =DEC2HEX(out_col0!C16) -> 205 | D16: =DEC2HEX(out_col0!D16) -> 31E0 | F16: =DEC2HEX(out_col0!F16) -> 10024
A17: =DEC2HEX(out_col0!A17) -> A95 | B17: =DEC2HEX(out_col0!B17) -> 1DE6 | C17: =DEC2HEX(out_col0!C17) -> 5881 | D17: =DEC2HEX(out_col0!D17) -> 567F | F17: =DEC2HEX(out_col0!F17) -> D77B
A18: =DEC2HEX(out_col0!A18) -> 21B0 | B18: =DEC2HEX(out_col0!B18) -> A0F0 | C18: =DEC2HEX(out_col0!C18) -> 29AE | D18: =DEC2HEX(out_col0!D18) -> BEB | F18: =DEC2HEX(out_col0!F18) -> F839
... A20: =DEC2HEX(out_col0!A20) -> 813 | B20: =DEC2HEX(out_col0!B20) -> 2E50 | C20: =DEC2HEX(out_col0!C20) -> 5EE0 | D20: =DEC2HEX(out_col0!D20) -> 5E8 | F20: =DEC2HEX(out_col0!F20) -> 9B2B
A21: =DEC2HEX(out_col0!A21) -> 0 | B21: =DEC2HEX(out_col0!B21) -> 1C34 | C21: =DEC2HEX(out_col0!C21) -> 1A85 | D21: =DEC2HEX(out_col0!D21) -> 1228 | F21: =DEC2HEX(out_col0!F21) -> 48E1 | H21: =DEC2HEX(out_col0!H21) -> 1 | I21: =DEC2HEX(out_col0!I21) -> 21527
A22: =DEC2HEX(out_col0!A22) -> 5F0F | B22: =DEC2HEX(out_col0!B22) -> 1 | C22: =DEC2HEX(out_col0!C22) -> 81F0 | D22: =DEC2HEX(out_col0!D22) -> F9B | F22: =DEC2HEX(out_col0!F22) -> F09B | H22: =DEC2HEX(out_col0!H22) -> 2 | I22: =DEC2HEX(out_col0!I22) -> 4770E | J22: =DEC2HEX(out_col0!J22) -> 68C35
A23: =DEC2HEX(out_col0!A23) -> 4D19 | B23: =DEC2HEX(out_col0!B23) -> 7C4C | C23: =DEC2HEX(out_col0!C23) -> 19A | D23: =DEC2HEX(out_col0!D23) -> 32DC | F23: =DEC2HEX(out_col0!F23) -> FDDB | H23: =DEC2HEX(out_col0!H23) -> 3 | I23: =DEC2HEX(out_col0!I23) -> 3340C | J23: =DEC2HEX(out_col0!J23) -> 9C041
A24: =DEC2HEX(out_col0!A24) -> 342F | B24: =DEC2HEX(out_col0!B24) -> E1 | C24: =DEC2HEX(out_col0!C24) -> 2D0 | D24: =DEC2HEX(out_col0!D24) -> 1734 | F24: =DEC2HEX(out_col0!F24) -> 4F14 | H24: =DEC2HEX(out_col0!H24) -> 4 | I24: =DEC2HEX(out_col0!I24) -> 3BCE8 | J24: =DEC2HEX(out_col0!J24) -> D7D29
A25: =DEC2HEX(out_col0!A25) -> D6F5 | B25: =DEC2HEX(out_col0!B25) -> 3A7D | C25: =DEC2HEX(out_col0!C25) -> 1176 | D25: =DEC2HEX(out_col0!D25) -> C570 | F25: =DEC2HEX(out_col0!F25) -> 1E858 | H25: =DEC2HEX(out_col0!H25) -> 5 | I25: =DEC2HEX(out_col0!I25) -> 68F3F | J25: =DEC2HEX(out_col0!J25) -> 140C68
A26: =DEC2HEX(out_col0!A26) -> 5010 | B26: =DEC2HEX(out_col0!B26) -> 1560 | C26: =DEC2HEX(out_col0!C26) -> 1BBA | D26: =DEC2HEX(out_col0!D26) -> 8AF | F26: =DEC2HEX(out_col0!F26) -> 89D9 | H26: somma | I26: =DEC2HEX(out_col0!I26) -> 140C68
A27: =DEC2HEX(out_col0!A27) -> CD83 | B27: =DEC2HEX(out_col0!B27) -> DA | C27: =DEC2HEX(out_col0!C27) -> 50E7 | D27: =DEC2HEX(out_col0!D27) -> D23F | F27: =DEC2HEX(out_col0!F27) -> 1F183
A28: =DEC2HEX(out_col0!A28) -> 1821 | B28: =DEC2HEX(out_col0!B28) -> 2124 | C28: =DEC2HEX(out_col0!C28) -> 19C8 | D28: =DEC2HEX(out_col0!D28) -> 54E8 | F28: =DEC2HEX(out_col0!F28) -> A7F5
A29: =DEC2HEX(out_col0!A29) -> 8936 | B29: =DEC2HEX(out_col0!B29) -> 12B1 | C29: =DEC2HEX(out_col0!C29) -> B0C6 | D29: =DEC2HEX(out_col0!D29) -> 1F38 | F29: =DEC2HEX(out_col0!F29) -> 16BE5
A30: =DEC2HEX(out_col0!A30) -> 93F6 | B30: =DEC2HEX(out_col0!B30) -> F807 | C30: =DEC2HEX(out_col0!C30) -> 1886 | D30: =DEC2HEX(out_col0!D30) -> D23C | F30: =DEC2HEX(out_col0!F30) -> 276BF
A31: =DEC2HEX(out_col0!A31) -> 1F94 | B31: =DEC2HEX(out_col0!B31) -> 3D08 | C31: =DEC2HEX(out_col0!C31) -> 639 | D31: =DEC2HEX(out_col0!D31) -> 7ACF | F31: =DEC2HEX(out_col0!F31) -> DDA4
A32: =DEC2HEX(out_col0!A32) -> 5220 | B32: =DEC2HEX(out_col0!B32) -> 1055 | C32: =DEC2HEX(out_col0!C32) -> DD2 | D32: =DEC2HEX(out_col0!D32) -> 7A10 | F32: =DEC2HEX(out_col0!F32) -> EA57
A33: =DEC2HEX(out_col0!A33) -> 3782 | B33: =DEC2HEX(out_col0!B33) -> 29B0 | C33: =DEC2HEX(out_col0!C33) -> A28 | D33: =DEC2HEX(out_col0!D33) -> 119D | F33: =DEC2HEX(out_col0!F33) -> 7CF7
A34: =DEC2HEX(out_col0!A34) -> 652C | B34: =DEC2HEX(out_col0!B34) -> 8630 | C34: =DEC2HEX(out_col0!C34) -> 7C4C | D34: =DEC2HEX(out_col0!D34) -> 20AA | F34: =DEC2HEX(out_col0!F34) -> 18852
A35: =DEC2HEX(out_col0!A35) -> 1CF2 | B35: =DEC2HEX(out_col0!B35) -> 849C | C35: =DEC2HEX(out_col0!C35) -> 1665 | D35: =DEC2HEX(out_col0!D35) -> B70C | F35: =DEC2HEX(out_col0!F35) -> 16EFF
A36: =DEC2HEX(out_col0!A36) -> 2311 | B36: =DEC2HEX(out_col0!B36) -> 35EE | C36: =DEC2HEX(out_col0!C36) -> 3B2 | D36: =DEC2HEX(out_col0!D36) -> 818 | F36: =DEC2HEX(out_col0!F36) -> 64C9
A37: =DEC2HEX(out_col0!A37) -> 50A | B37: =DEC2HEX(out_col0!B37) -> 2FA1 | C37: =DEC2HEX(out_col0!C37) -> 361F | D37: =DEC2HEX(out_col0!D37) -> 3FCF | F37: =DEC2HEX(out_col0!F37) -> AA99
A38: =DEC2HEX(out_col0!A38) -> 5D8 | B38: =DEC2HEX(out_col0!B38) -> B798 | C38: =DEC2HEX(out_col0!C38) -> 31D8 | D38: =DEC2HEX(out_col0!D38) -> 21FD | F38: =DEC2HEX(out_col0!F38) -> 11145
... A40: =DEC2HEX(out_col0!A40) -> 270 | B40: =DEC2HEX(out_col0!B40) -> 2EEC | C40: =DEC2HEX(out_col0!C40) -> 67C5 | D40: =DEC2HEX(out_col0!D40) -> 2808 | F40: =DEC2HEX(out_col0!F40) -> C129
A41: =DEC2HEX(out_col0!A41) -> 0 | B41: =DEC2HEX(out_col0!B41) -> 17C | C41: =DEC2HEX(out_col0!C41) -> 1C75 | D41: =DEC2HEX(out_col0!D41) -> 22B1 | F41: =DEC2HEX(out_col0!F41) -> 40A2 | H41: =DEC2HEX(out_col0!H41) -> 1 | I41: =DEC2HEX(out_col0!I41) -> 1DB22
A42: =DEC2HEX(out_col0!A42) -> 122A | B42: =DEC2HEX(out_col0!B42) -> 31 | C42: =DEC2HEX(out_col0!C42) -> 65AA | D42: =DEC2HEX(out_col0!D42) -> 239E | F42: =DEC2HEX(out_col0!F42) -> 9BA3 | H42: =DEC2HEX(out_col0!H42) -> 2 | I42: =DEC2HEX(out_col0!I42) -> 3ED59
...

Sheet out_col1
A1: =mem_dec!A1*mem_dec!A82 -> 8525 | B1: =mem_dec!B1*mem_dec!B82 -> 246 | C1: =mem_dec!C1*mem_dec!C82 -> 11242 | D1: =mem_dec!D1*mem_dec!D82 -> 4042 | F1: =SUM(A1:D1) -> 24055 | H1: 1 | I1: =F1+F6+F11+F16 -> 184341
A2: =mem_dec!A2*mem_dec!A83 -> 14190 | B2: =mem_dec!B2*mem_dec!B83 -> 45365 | C2: =mem_dec!C2*mem_dec!C83 -> 850 | D2: =mem_dec!D2*mem_dec!D83 -> 12768 | F2: =SUM(A2:D2) -> 73173 | H2: 2 | I2: =F2+F7+F12+F17 -> 237443
A3: =mem_dec!A3*mem_dec!A84 -> 36234 | B3: =mem_dec!B3*mem_dec!B84 -> 295 | C3: =mem_dec!C3*mem_dec!C84 -> 15552 | D3: =mem_dec!D3*mem_dec!D84 -> 3699 | F3: =SUM(A3:D3) -> 55780 | H3: 3 | I3: =F3+F8+F13+F18 -> 232931
A4: =mem_dec!A4*mem_dec!A85 -> 249 | B4: =mem_dec!B4*mem_dec!B85 -> 7728 | C4: =mem_dec!C4*mem_dec!C85 -> 4950 | D4: =mem_dec!D4*mem_dec!D85 -> 34560 | F4: =SUM(A4:D4) -> 47487 | H4: 4 | I4: =F4+F9+F14+F19 -> 329766
A5: =mem_dec!A5*mem_dec!A86 -> 1403 | B5: =mem_dec!B5*mem_dec!B86 -> 13464 | C5: =mem_dec!C5*mem_dec!C86 -> 12120 | D5: =mem_dec!D5*mem_dec!D86 -> 11180 | F5: =SUM(A5:D5) -> 38167 | H5: 5 | I5: =F5+F10+F15+F20 -> 162209
A6: =mem_dec!A6*mem_dec!A90 -> 639 | B6: =mem_dec!B6*mem_dec!B90 -> 10355 | C6: =mem_dec!C6*mem_dec!C90 -> 36654 | D6: =mem_dec!D6*mem_dec!D90 -> 33495 | F6: =SUM(A6:D6) -> 81143 | H6: somma | I6: =SUM(I1:I5) -> 1146690
A7: =mem_dec!A7*mem_dec!A91 -> 25560 | B7: =mem_dec!B7*mem_dec!B91 -> 2268 | C7: =mem_dec!C7*mem_dec!C91 -> 12300 | D7: =mem_dec!D7*mem_dec!D91 -> 48697 | F7: =SUM(A7:D7) -> 88825
A8: =mem_dec!A8*mem_dec!A92 -> 49022 | B8: =mem_dec!B8*mem_dec!B92 -> 754 | C8: =mem_dec!C8*mem_dec!C92 -> 32428 | D8: =mem_dec!D8*mem_dec!D92 -> 8478 | F8: =SUM(A8:D8) -> 90682
A9: =mem_dec!A9*mem_dec!A93 -> 50076 | B9: =mem_dec!B9*mem_dec!B93 -> 25245 | C9: =mem_dec!C9*mem_dec!C93 -> 7783 | D9: =mem_dec!D9*mem_dec!D93 -> 11040 | F9: =SUM(A9:D9) -> 94144
A10: =mem_dec!A10*mem_dec!A94 -> 2665 | B10: =mem_dec!B10*mem_dec!B94 -> 3300 | C10: =mem_dec!C10*mem_dec!C94 -> 11544 | D10: =mem_dec!D10*mem_dec!D94 -> 1083 | F10: =SUM(A10:D10) -> 18592
A11: =mem_dec!A11*mem_dec!A98 -> 4464 | B11: =mem_dec!B11*mem_dec!B98 -> 2923 | C11: =mem_dec!C11*mem_dec!C98 -> 1044 | D11: =mem_dec!D11*mem_dec!D98 -> 15407 | F11: =SUM(A11:D11) -> 23838
A12: =mem_dec!A12*mem_dec!A99 -> 8260 | B12: =mem_dec!B12*mem_dec!B99 -> 9246 | C12: =mem_dec!C12*mem_dec!C99 -> 546 | D12: =mem_dec!D12*mem_dec!D99 -> 2376 | F12: =SUM(A12:D12) -> 20428
A13: =mem_dec!A13*mem_dec!A100 -> 25604 | B13: =mem_dec!B13*mem_dec!B100 -> 10032 | C13: =mem_dec!C13*mem_dec!C100 -> 5180 | D13: =mem_dec!D13*mem_dec!D100 -> 6734 | F13: =SUM(A13:D13) -> 47550
A14: =mem_dec!A14*mem_dec!A101 -> 45201 | B14: =mem_dec!B14*mem_dec!B101 -> 3936 | C14: =mem_dec!C14*mem_dec!C101 -> 4485 | D14: =mem_dec!D14*mem_dec!D101 -> 45582 | F14: =SUM(A14:D14) -> 99204
A15: =mem_dec!A15*mem_dec!A102 -> 720 | B15: =mem_dec!B15*mem_dec!B102 -> 24823 | C15: =mem_dec!C15*mem_dec!C102 -> 17161 | D15: =mem_dec!D15*mem_dec!D102 -> 21242 | F15: =SUM(A15:D15) -> 63946
A16: =mem_dec!A16*mem_dec!A106 -> 387 | B16: =mem_dec!B16*mem_dec!B106 -> 19669 | C16: =mem_dec!C16*mem_dec!C106 -> 7661 | D16: =mem_dec!D16*mem_dec!D106 -> 27588 | F16: =SUM(A16:D16) -> 55305
A17: =mem_dec!A17*mem_dec!A107 -> 1848 | B17: =mem_dec!B17*mem_dec!B107 -> 17200 | C17: =mem_dec!C17*mem_dec!C107 -> 15290 | D17: =mem_dec!D17*mem_dec!D107 -> 20679 | F17: =SUM(A17:D17) -> 55017
A18: =mem_dec!A18*mem_dec!A108 -> 12936 | B18: =mem_dec!B18*mem_dec!B108 -> 2884 | C18: =mem_dec!C18*mem_dec!C108 -> 19400 | D18: =mem_dec!D18*mem_dec!D108 -> 3699 | F18: =SUM(A18:D18) -> 38919
A19: =mem_dec!A19*mem_dec!A109 -> 3224 | B19: =mem_dec!B19*mem_dec!B109 -> 18252 | C19: =mem_dec!C19*mem_dec!C109 -> 43263 | D19: =mem_dec!D19*mem_dec!D109 -> 24192 | F19: =SUM(A19:D19) -> 88931
A20: =mem_dec!A20*mem_dec!A110 -> 14310 | B20: =mem_dec!B20*mem_dec!B110 -> 18164 | C20: =mem_dec!C20*mem_dec!C110 -> 7104 | D20: =mem_dec!D20*mem_dec!D110 -> 1926 | F20: =SUM(A20:D20) -> 41504
A21: =mem_dec!A21*mem_dec!A81 -> 0 | B21: =mem_dec!B21*mem_dec!B81 -> 7220 | C21: =mem_dec!C21*mem_dec!C81 -> 6789 | D21: =mem_dec!D21*mem_dec!D81 -> 4648 | F21: =SUM(A21:D21) -> 18657 | H21: 1 | I21: =F21+F26+F31+F36 -> 130674
A22: =mem_dec!A22*mem_dec!A82 -> 24335 | B22: =mem_dec!B22*mem_dec!B82 -> 1 | C22: =mem_dec!C22*mem_dec!C82 -> 33264 | D22: =mem_dec!D22*mem_dec!D82 -> 3995 | F22: =SUM(A22:D22) -> 61595 | H22: 2 | I22: =F22+F27+F32+F37 -> 295714
A23: =mem_dec!A23*mem_dec!A83 -> 19737 | B23: =mem_dec!B23*mem_dec!B83 -> 31820 | C23: =mem_dec!C23*mem_dec!C83 -> 410 | D23: =mem_dec!D23*mem_dec!D83 -> 13020 | F23: =SUM(A23:D23) -> 64987 | H23: 3 | I23: =F23+F28+F33+F38 -> 308447
A24: =mem_dec!A24*mem_dec!A84 -> 13359 | B24: =mem_dec!B24*mem_dec!B84 -> 225 | C24: =mem_dec!C24*mem_dec!C84 -> 720 | D24: =mem_dec!D24*mem_dec!D84 -> 5940 | F24: =SUM(A24:D24) -> 20244 | H24: 4 | I24: =F24+F29+F34+F39 -> 294664
A25: =mem_dec!A25*mem_dec!A85 -> 55029 | B25: =mem_dec!B25*mem_dec!B85 -> 14973 | C25: =mem_dec!C25*mem_dec!C85 -> 4470 | D25: =mem_dec!D25*mem_dec!D85 -> 50544 | F25: =SUM(A25:D25) -> 125016 | H25: 5 | I25: =F25+F30+F35+F40 -> 365190
A26: =mem_dec!A26*mem_dec!A90 -> 25986 | B26: =mem_dec!B26*mem_dec!B90 -> 6213 | C26: =mem_dec!C26*mem_dec!C90 -> 13559 | D26: =mem_dec!D26*mem_dec!D90 -> 13167 | F26: =SUM(A26:D26) -> 58925 | H26: somma | I26: =SUM(I21:I25) -> 1394689
A27: =mem_dec!A27*mem_dec!A91 -> 52611 | B27: =mem_dec!B27*mem_dec!B91 -> 84 | C27: =mem_dec!C27*mem_dec!C91 -> 13900 | D27: =mem_dec!D27*mem_dec!D91 -> 48697 | F27: =SUM(A27:D27) -> 115292
A28: =mem_dec!A28*mem_dec!A92 -> 5597 | B28: =mem_dec!B28*mem_dec!B92 -> 5858 | C28: =mem_dec!C28*mem_dec!C92 -> 15972 | D28: =mem_dec!D28*mem_dec!D92 -> 5616 | F28: =SUM(A28:D28) -> 33043
A29: =mem_dec!A29*mem_dec!A93 -> 38948 | B29: =mem_dec!B29*mem_dec!B93 -> 42075 | C29: =mem_dec!C29*mem_dec!C93 -> 8041 | D29: =mem_dec!D29*mem_dec!D93 -> 34040 | F29: =SUM(A29:D29) -> 123104
A30: =mem_dec!A30*mem_dec!A94 -> 7257 | B30: =mem_dec!B30*mem_dec!B94 -> 54780 | C30: =mem_dec!C30*mem_dec!C94 -> 22776 | D30: =mem_dec!D30*mem_dec!D94 -> 4446 | F30: =SUM(A30:D30) -> 89259
A31: =mem_dec!A31*mem_dec!A99 -> 6580 | B31: =mem_dec!B31*mem_dec!B99 -> 9982 | C31: =mem_dec!C31*mem_dec!C99 -> 1534 | D31: =mem_dec!D31*mem_dec!D99 -> 5697 | F31: =SUM(A31:D31) -> 23793
A32: =mem_dec!A32*mem_dec!A100 -> 21608 | B32: =mem_dec!B32*mem_dec!B100 -> 17176 | C32: =mem_dec!C32*mem_dec!C100 -> 9028 | D32: =mem_dec!D32*mem_dec!D100 -> 5328 | F32: =SUM(A32:D32) -> 53140
A33: =mem_dec!A33*mem_dec!A101 -> 50141 | B33: =mem_dec!B33*mem_dec!B101 -> 38048 | C33: =mem_dec!C33*mem_dec!C101 -> 3900 | D33: =mem_dec!D33*mem_dec!D101 -> 35571 | F33: =SUM(A33:D33) -> 127660
A34: =mem_dec!A34*mem_dec!A102 -> 2800 | B34: =mem_dec!B34*mem_dec!B102 -> 54466 | C34: =mem_dec!C34*mem_dec!C102 -> 28165 | D34: =mem_dec!D34*mem_dec!D102 -> 19436 | F34: =SUM(A34:D34) -> 104867
A35: =mem_dec!A35*mem_dec!A103 -> 5580 | B35: =mem_dec!B35*mem_dec!B103 -> 49266 | C35: =mem_dec!C35*mem_dec!C103 -> 147 | D35: =mem_dec!D35*mem_dec!D103 -> 45760 | F35: =SUM(A35:D35) -> 100753
A36: =mem_dec!A36*mem_dec!A108 -> 6204 | B36: =mem_dec!B36*mem_dec!B108 -> 826 | C36: =mem_dec!C36*mem_dec!C108 -> 17200 | D36: =mem_dec!D36*mem_dec!D108 -> 5069 | F36: =SUM(A36:D36) -> 29299
A37: =mem_dec!A37*mem_dec!A109 -> 130 | B37: =mem_dec!B37*mem_dec!B109 -> 21372 | C37: =mem_dec!C37*mem_dec!C109 -> 21505 | D37: =mem_dec!D37*mem_dec!D109 -> 22680 | F37: =SUM(A37:D37) -> 65687
A38: =mem_dec!A38*mem_dec!A110 -> 1530 | B38: =mem_dec!B38*mem_dec!B110 -> 56165 | C38: =mem_dec!C38*mem_dec!C110 -> 8584 | D38: =mem_dec!D38*mem_dec!D110 -> 16478 | F38: =SUM(A38:D38) -> 82757
A39: =mem_dec!A39*mem_dec!A111 -> 3850 | B39: =mem_dec!B39*mem_dec!B111 -> 24780 | C39: =mem_dec!C39*mem_dec!C111 -> 10010 | D39: =mem_dec!D39*mem_dec!D111 -> 7809 | F39: =SUM(A39:D39) -> 46449
A40: =mem_dec!A40*mem_dec!A112 -> 3648 | B40: =mem_dec!B40*mem_dec!B112 -> 18249 | C40: =mem_dec!C40*mem_dec!C112 -> 22470 | D40: =mem_dec!D40*mem_dec!D112 -> 5795 | F40: =SUM(A40:D40) -> 50162
...

Sheet hex_out_col1
A1: =DEC2HEX(out_col1!A1) -> 214D | B1: =DEC2HEX(out_col1!B1) -> F6 | C1: =DEC2HEX(out_col1!C1) -> 2BEA | D1: =DEC2HEX(out_col1!D1) -> FCA | F1: =DEC2HEX(out_col1!F1) -> 5DF7 | H1: 1 | I1: =DEC2HEX(out_col1!I1) -> 2D015
A2: =DEC2HEX(out_col1!A2) -> 376E | B2: =DEC2HEX(out_col1!B2) -> B135 | C2: =DEC2HEX(out_col1!C2) -> 352 | D2: =DEC2HEX(out_col1!D2) -> 31E0 | F2: =DEC2HEX(out_col1!F2) -> 11DD5 | H2: 2 | I2: =DEC2HEX(out_col1!I2) -> 39F83
A3: =DEC2HEX(out_col1!A3) -> 8D8A | B3: =DEC2HEX(out_col1!B3) -> 127 | C3: =DEC2HEX(out_col1!C3) -> 3CC0 | D3: =DEC2HEX(out_col1!D3) -> E73 | F3: =DEC2HEX(out_col1!F3) -> D9E4 | H3: 3 | I3: =DEC2HEX(out_col1!I3) -> 38DE3
A4: =DEC2HEX(out_col1!A4) -> F9 | B4: =DEC2HEX(out_col1!B4) -> 1E30 | C4: =DEC2HEX(out_col1!C4) -> 1356 | D4: =DEC2HEX(out_col1!D4) -> 8700 | F4: =DEC2HEX(out_col1!F4) -> B97F | H4: 4 | I4: =DEC2HEX(out_col1!I4) -> 50826
A5: =DEC2HEX(out_col1!A5) -> 57B | B5: =DEC2HEX(out_col1!B5) -> 3498 | C5: =DEC2HEX(out_col1!C5) -> 2F58 | D5: =DEC2HEX(out_col1!D5) -> 2BAC | F5: =DEC2HEX(out_col1!F5) -> 9517 | H5: 5 | I5: =DEC2HEX(out_col1!I5) -> 279A1
A6: =DEC2HEX(out_col1!A6) -> 27F | B6: =DEC2HEX(out_col1!B6) -> 2873 | C6: =DEC2HEX(out_col1!C6) -> 8F2E | D6: =DEC2HEX(out_col1!D6) -> 82D7 | F6: =DEC2HEX(out_col1!F6) -> 13CF7 | H6: somma | I6: =DEC2HEX(out_col1!I6) -> 117F42
A7: =DEC2HEX(out_col1!A7) -> 63D8 | B7: =DEC2HEX(out_col1!B7) -> 8DC | C7: =DEC2HEX(out_col1!C7) -> 300C | D7: =DEC2HEX(out_col1!D7) -> BE39 | F7: =DEC2HEX(out_col1!F7) -> 15AF9
A8: =DEC2HEX(out_col1!A8) -> BF7E | B8: =DEC2HEX(out_col1!B8) -> 2F2 | C8: =DEC2HEX(out_col1!C8) -> 7EAC | D8: =DEC2HEX(out_col1!D8) -> 211E | F8: =DEC2HEX(out_col1!F8) -> 1623A
A9: =DEC2HEX(out_col1!A9) -> C39C | B9: =DEC2HEX(out_col1!B9) -> 629D | C9: =DEC2HEX(out_col1!C9) -> 1E67 | D9: =DEC2HEX(out_col1!D9) -> 2B20 | F9: =DEC2HEX(out_col1!F9) -> 16FC0
A10: =DEC2HEX(out_col1!A10) -> A69 | B10: =DEC2HEX(out_col1!B10) -> CE4 | C10: =DEC2HEX(out_col1!C10) -> 2D18 | D10: =DEC2HEX(out_col1!D10) -> 43B | F10: =DEC2HEX(out_col1!F10) -> 48A0
A11: =DEC2HEX(out_col1!A11) -> 1170 | B11: =DEC2HEX(out_col1!B11) -> B6B | C11: =DEC2HEX(out_col1!C11) -> 414 | D11: =DEC2HEX(out_col1!D11) -> 3C2F | F11: =DEC2HEX(out_col1!F11) -> 5D1E
A12: =DEC2HEX(out_col1!A12) -> 2044 | B12: =DEC2HEX(out_col1!B12) -> 241E | C12: =DEC2HEX(out_col1!C12) -> 222 | D12: =DEC2HEX(out_col1!D12) -> 948 | F12: =DEC2HEX(out_col1!F12) -> 4FCC
A13: =DEC2HEX(out_col1!A13) -> 6404 | B13: =DEC2HEX(out_col1!B13) -> 2730 | C13: =DEC2HEX(out_col1!C13) -> 143C | D13: =DEC2HEX(out_col1!D13) -> 1A4E | F13: =DEC2HEX(out_col1!F13) -> B9BE
A14: =DEC2HEX(out_col1!A14) -> B091 | B14: =DEC2HEX(out_col1!B14) -> F60 | C14: =DEC2HEX(out_col1!C14) -> 1185 | D14: =DEC2HEX(out_col1!D14) -> B20E | F14: =DEC2HEX(out_col1!F14) -> 18384
A15: =DEC2HEX(out_col1!A15) -> 2D0 | B15: =DEC2HEX(out_col1!B15) -> 60F7 | C15: =DEC2HEX(out_col1!C15) -> 4309 | D15: =DEC2HEX(out_col1!D15) -> 52FA | F15: =DEC2HEX(out_col1!F15) -> F9CA
A16: =DEC2HEX(out_col1!A16) -> 183 | B16: =DEC2HEX(out_col1!B16) -> 4CD5 | C16: =DEC2HEX(out_col1!C16) -> 1DED | D16: =DEC2HEX(out_col1!D16) -> 6BC4 | F16: =DEC2HEX(out_col1!F16) -> D809
A17: =DEC2HEX(out_col1!A17) -> 738 | B17: =DEC2HEX(out_col1!B17) -> 4330 | C17: =DEC2HEX(out_col1!C17) -> 3BBA | D17: =DEC2HEX(out_col1!D17) -> 50C7 | F17: =DEC2HEX(out_col1!F17) -> D6E9
A18: =DEC2HEX(out_col1!A18) -> 3288 | B18: =DEC2HEX(out_col1!B18) -> B44 | C18: =DEC2HEX(out_col1!C18) -> 4BC8 | D18: =DEC2HEX(out_col1!D18) -> E73 | F18: =DEC2HEX(out_col1!F18) -> 9807
... A20: =DEC2HEX(out_col1!A20) -> 37E6 | B20: =DEC2HEX(out_col1!B20) -> 46F4 | C20: =DEC2HEX(out_col1!C20) -> 1BC0 | D20: =DEC2HEX(out_col1!D20) -> 786 | F20: =DEC2HEX(out_col1!F20) -> A220
A21: =DEC2HEX(out_col1!A21) -> 0 | B21: =DEC2HEX(out_col1!B21) -> 1C34 | C21: =DEC2HEX(out_col1!C21) -> 1A85 | D21: =DEC2HEX(out_col1!D21) -> 1228 | F21: =DEC2HEX(out_col1!F21) -> 48E1 | H21: 1 | I21: =DEC2HEX(out_col1!I21) -> 1FE72
A22: =DEC2HEX(out_col1!A22) -> 5F0F | B22: =DEC2HEX(out_col1!B22) -> 1 | C22: =DEC2HEX(out_col1!C22) -> 81F0 | D22: =DEC2HEX(out_col1!D22) -> F9B | F22: =DEC2HEX(out_col1!F22) -> F09B | H22: 2 | I22: =DEC2HEX(out_col1!I22) -> 48322
A23: =DEC2HEX(out_col1!A23) -> 4D19 | B23: =DEC2HEX(out_col1!B23) -> 7C4C | C23: =DEC2HEX(out_col1!C23) -> 19A | D23: =DEC2HEX(out_col1!D23) -> 32DC | F23: =DEC2HEX(out_col1!F23) -> FDDB | H23: 3 | I23: =DEC2HEX(out_col1!I23) -> 4B4DF
A24: =DEC2HEX(out_col1!A24) -> 342F | B24: =DEC2HEX(out_col1!B24) -> E1 | C24: =DEC2HEX(out_col1!C24) -> 2D0 | D24: =DEC2HEX(out_col1!D24) -> 1734 | F24: =DEC2HEX(out_col1!F24) -> 4F14 | H24: 4 | I24: =DEC2HEX(out_col1!I24) -> 47F08
A25: =DEC2HEX(out_col1!A25) -> D6F5 | B25: =DEC2HEX(out_col1!B25) -> 3A7D | C25: =DEC2HEX(out_col1!C25) -> 1176 | D25: =DEC2HEX(out_col1!D25) -> C570 | F25: =DEC2HEX(out_col1!F25) -> 1E858 | H25: 5 | I25: =DEC2HEX(out_col1!I25) -> 59286
A26: =DEC2HEX(out_col1!A26) -> 6582 | B26: =DEC2HEX(out_col1!B26) -> 1845 | C26: =DEC2HEX(out_col1!C26) -> 34F7 | D26: =DEC2HEX(out_col1!D26) -> 336F | F26: =DEC2HEX(out_col1!F26) -> E62D | H26: somma | I26: =DEC2HEX(out_col1!I26) -> 154801
A27: =DEC2HEX(out_col1!A27) -> CD83 | B27: =DEC2HEX(out_col1!B27) -> 54 | C27: =DEC2HEX(out_col1!C27) -> 364C | D27: =DEC2HEX(out_col1!D27) -> BE39 | F27: =DEC2HEX(out_col1!F27) -> 1C25C
A28: =DEC2HEX(out_col1!A28) -> 15DD | B28: =DEC2HEX(out_col1!B28) -> 16E2 | C28: =DEC2HEX(out_col1!C28) -> 3E64 | D28: =DEC2HEX(out_col1!D28) -> 15F0 | F28: =DEC2HEX(out_col1!F28) -> 8113
A29: =DEC2HEX(out_col1!A29) -> 9824 | B29: =DEC2HEX(out_col1!B29) -> A45B | C29: =DEC2HEX(out_col1!C29) -> 1F69 | D29: =DEC2HEX(out_col1!D29) -> 84F8 | F29: =DEC2HEX(out_col1!F29) -> 1E0E0
A30: =DEC2HEX(out_col1!A30) -> 1C59 | B30: =DEC2HEX(out_col1!B30) -> D5FC | C30: =DEC2HEX(out_col1!C30) -> 58F8 | D30: =DEC2HEX(out_col1!D30) -> 115E | F30: =DEC2HEX(out_col1!F30) -> 15CAB
A31: =DEC2HEX(out_col1!A31) -> 19B4 | B31: =DEC2HEX(out_col1!B31) -> 26FE | C31: =DEC2HEX(out_col1!C31) -> 5FE | D31: =DEC2HEX(out_col1!D31) -> 1641 | F31: =DEC2HEX(out_col1!F31) -> 5CF1
A32: =DEC2HEX(out_col1!A32) -> 5468 | B32: =DEC2HEX(out_col1!B32) -> 4318 | C32: =DEC2HEX(out_col1!C32) -> 2344 | D32: =DEC2HEX(out_col1!D32) -> 14D0 | F32: =DEC2HEX(out_col1!F32) -> CF94
A33: =DEC2HEX(out_col1!A33) -> C3DD | B33: =DEC2HEX(out_col1!B33) -> 94A0 | C33: =DEC2HEX(out_col1!C33) -> F3C | D33: =DEC2HEX(out_col1!D33) -> 8AF3 | F33: =DEC2HEX(out_col1!F33) -> 1F2AC
A34: =DEC2HEX(out_col1!A34) -> AF0 | B34: =DEC2HEX(out_col1!B34) -> D4C2 | C34: =DEC2HEX(out_col1!C34) -> 6E05 | D34: =DEC2HEX(out_col1!D34) -> 4BEC | F34: =DEC2HEX(out_col1!F34) -> 199A3
A35: =DEC2HEX(out_col1!A35) -> 15CC | B35: =DEC2HEX(out_col1!B35) -> C072 | C35: =DEC2HEX(out_col1!C35) -> 93 | D35: =DEC2HEX(out_col1!D35) -> B2C0 | F35: =DEC2HEX(out_col1!F35) -> 18991
A36: =DEC2HEX(out_col1!A36) -> 183C | B36: =DEC2HEX(out_col1!B36) -> 33A | C36: =DEC2HEX(out_col1!C36) -> 4330 | D36: =DEC2HEX(out_col1!D36) -> 13CD | F36: =DEC2HEX(out_col1!F36) -> 7273
A37: =DEC2HEX(out_col1!A37) -> 82 | B37: =DEC2HEX(out_col1!B37) -> 537C | C37: =DEC2HEX(out_col1!C37) -> 5401 | D37: =DEC2HEX(out_col1!D37) -> 5898 | F37: =DEC2HEX(out_col1!F37) -> 10097
A38: =DEC2HEX(out_col1!A38) -> 5FA | B38: =DEC2HEX(out_col1!B38) -> DB65 | C38: =DEC2HEX(out_col1!C38) -> 2188 | D38: =DEC2HEX(out_col1!D38) -> 405E | F38: =DEC2HEX(out_col1!F38) -> 14345
... A40: =DEC2HEX(out_col1!A40) -> E40 | B40: =DEC2HEX(out_col1!B40) -> 4749 | C40: =DEC2HEX(out_col1!C40) -> 57C6 | D40: =DEC2HEX(out_col1!D40) -> 16A3 | F40: =DEC2HEX(out_col1!F40) -> C3F2
A41: =DEC2HEX(out_col1!A41) -> 0 | B41: =DEC2HEX(out_col1!B41) -> 17C | C41: =DEC2HEX(out_col1!C41) -> 1C75 | D41: =DEC2HEX(out_col1!D41) -> 22B1 | F41: =DEC2HEX(out_col1!F41) -> 40A2 | H41: 1 | I41: =DEC2HEX(out_col1!I41) -> 2744E
A42: =DEC2HEX(out_col1!A42) -> 122A | B42: =DEC2HEX(out_col1!B42) -> 31 | C42: =DEC2HEX(out_col1!C42) -> 65AA | D42: =DEC2HEX(out_col1!D42) -> 239E | F42: =DEC2HEX(out_col1!F42) -> 9BA3 | H42: 2 | I42: =DEC2HEX(out_col1!I42) -> 428C2
...
